2020-03-12 10:45:04,629 ERROR: Exception on /login [POST] [in d:\graduate\venv\lib\site-packages\flask\app.py:1891]
Traceback (most recent call last):
  File "d:\graduate\venv\lib\site-packages\flask\app.py", line 2446, in wsgi_app
    response = self.full_dispatch_request()
  File "d:\graduate\venv\lib\site-packages\flask\app.py", line 1951, in full_dispatch_request
    rv = self.handle_user_exception(e)
  File "d:\graduate\venv\lib\site-packages\flask\app.py", line 1820, in handle_user_exception
    reraise(exc_type, exc_value, tb)
  File "d:\graduate\venv\lib\site-packages\flask\_compat.py", line 39, in reraise
    raise value
  File "d:\graduate\venv\lib\site-packages\flask\app.py", line 1949, in full_dispatch_request
    rv = self.dispatch_request()
  File "d:\graduate\venv\lib\site-packages\flask\app.py", line 1935, in dispatch_request
    return self.view_functions[rule.endpoint](**req.view_args)
  File "D:\graduate\RealTimeDataTransfer\app\routes.py", line 40, in login
    if user is None or not user.check_password(form.password.data):
  File "D:\graduate\RealTimeDataTransfer\app\models.py", line 34, in check_password
    return check_password_hash(self.password_hash, password)
  File "d:\graduate\venv\lib\site-packages\werkzeug\security.py", line 218, in check_password_hash
    if pwhash.count("$") < 2:
AttributeError: 'NoneType' object has no attribute 'count'
2020-03-12 10:46:58,631 INFO: Microblog startup [in D:\graduate\RealTimeDataTransfer\app\__init__.py:46]
2020-03-12 10:49:00,087 INFO: Microblog startup [in D:\graduate\RealTimeDataTransfer\app\__init__.py:46]
2020-03-12 10:49:01,520 ERROR: Exception on /index [GET] [in d:\graduate\venv\lib\site-packages\flask\app.py:1891]
Traceback (most recent call last):
  File "d:\graduate\venv\lib\site-packages\flask\app.py", line 2446, in wsgi_app
    response = self.full_dispatch_request()
  File "d:\graduate\venv\lib\site-packages\flask\app.py", line 1951, in full_dispatch_request
    rv = self.handle_user_exception(e)
  File "d:\graduate\venv\lib\site-packages\flask\app.py", line 1820, in handle_user_exception
    reraise(exc_type, exc_value, tb)
  File "d:\graduate\venv\lib\site-packages\flask\_compat.py", line 39, in reraise
    raise value
  File "d:\graduate\venv\lib\site-packages\flask\app.py", line 1949, in full_dispatch_request
    rv = self.dispatch_request()
  File "d:\graduate\venv\lib\site-packages\flask\app.py", line 1935, in dispatch_request
    return self.view_functions[rule.endpoint](**req.view_args)
  File "d:\graduate\venv\lib\site-packages\flask_login\utils.py", line 272, in decorated_view
    return func(*args, **kwargs)
  File "D:\graduate\RealTimeDataTransfer\app\routes.py", line 14, in index
    sensors = current_user.sensors()
TypeError: 'AppenderBaseQuery' object is not callable
2020-03-12 10:49:14,888 INFO: Microblog startup [in D:\graduate\RealTimeDataTransfer\app\__init__.py:46]
2020-03-12 10:49:54,119 INFO: Microblog startup [in D:\graduate\RealTimeDataTransfer\app\__init__.py:46]
2020-03-12 10:55:50,177 INFO: Microblog startup [in D:\graduate\RealTimeDataTransfer\app\__init__.py:48]
2020-03-12 10:56:06,008 INFO: Microblog startup [in D:\graduate\RealTimeDataTransfer\app\__init__.py:49]
2020-03-12 11:25:36,018 ERROR: Exception on / [GET] [in d:\graduate\venv\lib\site-packages\flask\app.py:1891]
Traceback (most recent call last):
  File "d:\graduate\venv\lib\site-packages\flask\app.py", line 2446, in wsgi_app
    response = self.full_dispatch_request()
  File "d:\graduate\venv\lib\site-packages\flask\app.py", line 1951, in full_dispatch_request
    rv = self.handle_user_exception(e)
  File "d:\graduate\venv\lib\site-packages\flask\app.py", line 1820, in handle_user_exception
    reraise(exc_type, exc_value, tb)
  File "d:\graduate\venv\lib\site-packages\flask\_compat.py", line 39, in reraise
    raise value
  File "d:\graduate\venv\lib\site-packages\flask\app.py", line 1949, in full_dispatch_request
    rv = self.dispatch_request()
  File "d:\graduate\venv\lib\site-packages\flask\app.py", line 1935, in dispatch_request
    return self.view_functions[rule.endpoint](**req.view_args)
  File "d:\graduate\venv\lib\site-packages\flask_login\utils.py", line 270, in decorated_view
    elif not current_user.is_authenticated:
  File "d:\graduate\venv\lib\site-packages\werkzeug\local.py", line 347, in __getattr__
    return getattr(self._get_current_object(), name)
  File "d:\graduate\venv\lib\site-packages\werkzeug\local.py", line 306, in _get_current_object
    return self.__local()
  File "d:\graduate\venv\lib\site-packages\flask_login\utils.py", line 26, in <lambda>
    current_user = LocalProxy(lambda: _get_user())
  File "d:\graduate\venv\lib\site-packages\flask_login\utils.py", line 346, in _get_user
    current_app.login_manager._load_user()
  File "d:\graduate\venv\lib\site-packages\flask_login\login_manager.py", line 318, in _load_user
    user = self._user_callback(user_id)
  File "D:\graduate\RealTimeDataTransfer\app\models.py", line 62, in load_user
    return use_obj
NameError: name 'use_obj' is not defined
2020-03-12 11:26:15,809 INFO: Microblog startup [in D:\graduate\RealTimeDataTransfer\app\__init__.py:49]
2020-03-12 11:36:55,012 INFO: Microblog startup [in D:\graduate\RealTimeDataTransfer\app\__init__.py:49]
2020-03-12 11:37:14,987 INFO: Microblog startup [in D:\graduate\RealTimeDataTransfer\app\__init__.py:49]
2020-03-12 11:43:09,284 INFO: Microblog startup [in D:\graduate\RealTimeDataTransfer\app\__init__.py:49]
2020-03-12 11:43:37,955 INFO: Microblog startup [in D:\graduate\RealTimeDataTransfer\app\__init__.py:49]
2020-03-12 11:44:33,971 INFO: Microblog startup [in D:\graduate\RealTimeDataTransfer\app\__init__.py:49]
